Workbook

Sheet Control Panel
A1: ⚙ NO DICE BOROUGH LTD · CONTROL PANEL · Central Input Hub
A2: 🔵 Blue cells = editable inputs 🟢 Green cells = live outputs (read only) ⚠ Password to unlock other sheets: NoDice2026
B4: 1. DEAL STRUCTURE | E4: LIVE OUTPUTS (auto-update) | H4: QUICK NAVIGATION
B5: Investment Amount (£) | C5: ='Investment Valuation 1'!D7 | E5: Pre-Money Valuation | F5: ='Investment Valuation 1'!C7 | H5: 📊 Investor Summary | I5: =HYPERLINK("#'Investor Summary'!A1","→ Open")
B6: EBITDA Multiple (×) | C6: ='Investment Valuation 1'!B7 | E6: Post-Money Valuation | F6: ='Investment Valuation 1'!E7 | H6: 💰 Cash Flow Forecast | I6: =HYPERLINK("#'Cash Flow Forecast'!A1","→ Open")
B7: Investor Equity % (auto — set by multiple) | C7: ='Investment Valuation 1'!G7 | E7: Founder Equity % (auto) | F7: ='Investment Valuation 1'!F7 | H7: 📋 Dividend & Distribution | I7: =HYPERLINK("#'Dividend & Distribution Model'!A1","→ Open")
B9: 2. SCENARIO SELECTION | E9: REVENUE & PROFIT | H9: 📈 Scenario Planning
B10: Active Scenario | C10: =Inputs!C6 | E10: Forecast Revenue (base) | F10: ='Base Case Forecast'!N6 | H10: 🏦 Investment Valuation | I10: =HYPERLINK("#'Investment Valuation 1'!A1","→ Open")
B11: ↑ Changes this cell updates entire model via Inputs!C6 | E11: Forecast Profit (base) | F11: ='Dividend & Distribution Model'!B14
B12: Conservative Growth % | C12: ='Scenario Planning'!B93 | E12: Active Growth Rate (auto) | F12: =Inputs!C7 | H12: 📈 Scenario Planning | I12: =HYPERLINK("#'Scenario Planning'!A1","→ Open")
B13: Optimistic Growth % | C13: ='Scenario Planning'!B95 | E13: Profit Margin % | F13: ='Base Case Forecast'!N17 | H13: ⬇ Downside Scenario | I13: =HYPERLINK("#'Downside Scenario'!A1","→ Open")
B15: 3. DIVIDEND & RETURNS | E15: INVESTOR RETURN OUTPUTS | H15: 📉 Investor Returns
B16: Preferred Return % (default 8%) | C16: ='Dividend & Distribution Model'!B23 | E16: Preferred Return (£) | F16: ='Dividend & Distribution Model'!B28 | H16: 💸 Dividend & Distribution | I16: =HYPERLINK("#'Dividend & Distribution Model'!A1","→ Open")
B17: A-Share Priority — Quarterly (£) | C17: ='Dividend & Distribution Model'!B17 | E17: A-Share Priority — Annual (£) | F17: ='Dividend & Distribution Model'!B18 | H17: 📊 Investor Returns sheet | I17: =HYPERLINK("#'Investor Returns'!A1","→ Open")
B18: Remaining Profit Pool | C18: ='Dividend & Distribution Model'!B29 | E18: Total → Investor (Year 1) | F18: ='Dividend & Distribution Model'!B41 | H18: 📋 Base Case Forecast | I18: =HYPERLINK("#'Base Case Forecast'!A1","→ Open")
B19: Total → Investor (Year 1) | C19: ='Dividend & Distribution Model'!B41 | E19: Cash-on-Cash Return (Year 1) | F19: ='Dividend & Distribution Model'!B41/'Investment Valuation 1'!D7 | H19: 🔑 Inputs Hub | I19: =HYPERLINK("#'Inputs'!A1","→ Open")
B20: Simple Payback Period | C20: ='Investment Valuation 1'!D7/'Dividend & Distribution Model'!B41 | E20: 5-Year IRR (estimated) | F20: ='Investor Returns'!B36 | H20: 📣 Marketing / Google Ads | I20: =HYPERLINK("#'Google Budget'!A1","→ Open")
B22: 4. COST & CASH ASSUMPTIONS | E22: CASH POSITION OUTPUTS | H22: 💵 Base Case Forecast
B23: Director Salary — Annual (£) | C23: ='Base Case Forecast'!B54 | E23: Peak Cash Balance | F23: =MAX('Cash Flow Forecast'!B30:M30) | H23: 💵 Cash Flow Forecast | I23: =HYPERLINK("#'Cash Flow Forecast'!A1","→ Open")
B24: Fixed Cost Uplift % | C24: ='Base Case Forecast'!B53 | E24: Minimum Cash Balance | F24: =MIN('Cash Flow Forecast'!B30:M30) | H24: 📉 Downside Scenario | I24: =HYPERLINK("#'Downside Scenario'!A1","→ Open")
B25: Variable Cost Cap (% of rev) | C25: ='Base Case Forecast'!B55 | E25: 3-Month Reserve Target | F25: =('Base Case Forecast'!N8+'Base Case Forecast'!N9+'Base Case Forecast'!N13+'Base Case Forecast'!B54)/12*3 | H25: 📅 Monthly Summary | I25: =HYPERLINK("#'Monthly Summary'!A1","→ Open")
B26: Rent % of Quarterly Revenue | C26: ='Base Case Forecast'!B56 | E26: Cash Safety Floor (model) | F26: ='Cash Flow Forecast'!G39 | H26: 🔢 Capacity Model | I26: =HYPERLINK("#'Capacity Model'!A1","→ Open")
B27: Cash Safety Floor Target (£) | C27: ='Cash Flow Forecast'!G39 | E27: Annual Net VAT Payable (est.) | F27: ='Base Case Forecast'!N14 | H27: 💻 Tech Optimisation | I27: =HYPERLINK("#'Tech Optimisation'!A1","→ Open")
B29: 5. MARKETING SPEND | E29: MARKETING RETURNS | H29: 📣 Google Budget
B30: Google Ads — Weekly Budget (£) | C30: =Inputs!C56 | E30: Google Ads — Annual Budget | F30: ='Google Budget'!F63 | H30: 🌐 Google Budget sheet | I30: =HYPERLINK("#'Google Budget'!A1","→ Open")
B31: Adjusted CPC (GA4 verified) | C31: ='Google Budget'!F65 | E31: Annual Clicks (estimated) | F31: ='Google Budget'!F75 | H31: 📊 Marketing Budget | I31: =HYPERLINK("#'Marketing Budget'!A1","→ Open")
B32: Marketing ROAS (5.62× verified) | C32: ='Google Budget'!F87 | E32: Net Profit from Ads | F32: ='Google Budget'!F81 | H32: 🎯 Events Strategy | I32: =HYPERLINK("#'Events Strategy'!A1","→ Open")
B34: 6. 5-YEAR PROJECTION | E34: LONG-TERM OUTPUTS | H34: 📅 Investor Returns (5yr)
B35: Annual Growth Rate (Years 2–5) | C35: ='Investor Returns'!B47 | E35: 5-Year IRR | F35: ='Investor Returns'!B36 | H35: 📉 Investor Returns sheet | I35: =HYPERLINK("#'Investor Returns'!A1","→ Open")
A36: The EBITDA multiplier controls the entire deal valuation. Change Founder Tools!C5 to test alternative pricing (current 0.76× = distressed entry). | B36: Year 5 Exit Multiple (×) | C36: ='Investor Returns'!B48 | E36: Year 5 Investor Exit Value | F36: ='Investor Returns'!B33 | H36: 📊 Investment Rounds | I36: =HYPERLINK("#'Investment Rounds Model'!A1","→ Open")
A38: ★ All blue cells update the full model in real time. Green cells are read-only outputs. Password to unlock other sheets: NoDice2026 · No Dice Borough LTD · Confidential
A41: 🔐 FOUNDER TOOLS — EBITDA Multiplier & Valuation Control (Password protected — investor password does not apply here)
A42: The EBITDA multiplier controls the entire deal valuation. Changing it updates pre-money, post-money, equity %, investor returns and all downstream calculations automatically. To adjust: unprotect the "Founder Tools" sheet using password ND_FOUNDER_2026, change the multiplier, then re-protect.
B43: A Shares (50% equity > 5% threshold) | C43: ='Investment Valuation 1'!B7 | E43: A/B Threshold (5% of post-money) | F43: £7,900 | H43: → Founder Tools sheet | I43: =HYPERLINK("#'Founder Tools'!A1","→ Open")
B44: 3.0× → | C44: ='Investment Valuation 1'!A7*3+'Investment Valuation 1'!D7 | E44: 3.5× → | F44: ='Investment Valuation 1'!A7*3.5+'Investment Valuation 1'!D7 | H44: Scenarios below show post-money at each multiple
B45: 4.0× → | C45: ='Investment Valuation 1'!A7*4+'Investment Valuation 1'!D7 | E45: 4.5× → | F45: ='Investment Valuation 1'!A7*4.5+'Investment Valuation 1'!D7 | H45: (All post-money = EBITDA × multiple + £150k investment)
B47: Current Investor Share Class | C47: A Shares (31.79% > 10% threshold) | E47: A/B Threshold (10% of post-money) | F47: £47,182
B48: ⚡ A Shares = investor equity ≥10% · voting rights included | B Shares = <10% · non-voting · all economic rights identical

Sheet Founder Tools
A1: 🔐 FOUNDER TOOLS — NO DICE BOROUGH LTD · EBITDA Multiplier & Valuation Control · Password: ND_FOUNDER_2026
A2: ⚠ This sheet is for the founder only. The EBITDA multiplier is the only editable cell. All other values update automatically. Investor password (NoDice2026) does NOT unlock this sheet.
B4: EBITDA MULTIPLE — THE ONLY EDITABLE CELL | E4: LIVE VALUATION OUTPUT (auto-updates)
B5: EBITDA Multiple (×) | C5: 0.8592 | E5: EBITDA 2025 (verified) | F5: ='Monthly Summary'!I15
B6: ↑ Change this value to update the entire model. Try: 0.5× · 0.86× · 1.0× · 1.5× · 2.0× | E6: Pre-Money Valuation | F6: ='Investment Valuation 1'!C7
E7: Post-Money Valuation | F7: ='Investment Valuation 1'!E7
E8: Investor Equity % | F8: ='Investment Valuation 1'!G7
E9: Founder Equity % | F9: ='Investment Valuation 1'!F7
B11: MULTIPLE SCENARIO COMPARISON — All figures live (update when you change cell C5)
B12: Multiple | C12: Pre-Money | D12: Post-Money | E12: Inv. Equity % | F12: Founder Equity % | G12: Total→Investor | H12: Cash-on-Cash | I12: Payback
B13: 0.5× | C13: 0.5× | D13: 45975 | E13: 124975 | F13: 0.6321 | G13: 0.3679 | H13: ='Dividend & Distribution Model'!B41 | I13: =79000/'Dividend & Distribution Model'!B41
B14: 0.86× ← CURRENT | C14: 0.86× | D14: 79077 | E14: 158077 | F14: 0.4998 | G14: 0.5002 | H14: ='Dividend & Distribution Model'!B41 | I14: =79000/'Dividend & Distribution Model'!B41
B15: 1.0× | C15: 1.0× | D15: 91950 | E15: 170950 | F15: 0.4621 | G15: 0.5379 | H15: ='Dividend & Distribution Model'!B41 | I15: =79000/'Dividend & Distribution Model'!B41
B16: 1.5× | C16: 1.5× | D16: 137925 | E16: 216925 | F16: 0.3642 | G16: 0.6358 | H16: ='Dividend & Distribution Model'!B41 | I16: =79000/'Dividend & Distribution Model'!B41
B17: 2.0× | C17: 2.0× | D17: 183900 | E17: 262900 | F17: 0.3005 | G17: 0.6995 | H17: ='Dividend & Distribution Model'!B41 | I17: =79000/'Dividend & Distribution Model'!B41
B19: KEY IMPACT OF MULTIPLIER CHANGE — What changes, what stays the same
B20: ✓ Changes: | C20: Pre-money valuation · Post-money valuation · Investor equity % · Founder equity %
B21: ✓ Changes: | C21: All equity-based calculations in Investor Returns and DDM sheets
B22: ✗ Stays same: | C22: EBITDA profit figures · Revenue forecasts · Operating costs · Cash flow
B23: ✗ Stays same: | C23: Preferred return (£0 — pure pro-rata) · A-share priority (£0 — pure pro-rata) — both removed
B24: ⚠ Note: | C24: Changing the multiple changes the investor's equity stake — discuss with investor before finalising
A26: ★ FOUNDER ONLY · Password: ND_FOUNDER_2026 · Investor password (NoDice2026) will NOT unprotect this sheet · No Dice Borough Ltd · Confidential

Sheet Investor Summary
A1: NO DICE BOROUGH LTD · INVESTOR SUMMARY
A2: =UPPER("Active Scenario: "&Inputs!C6&" · Revenue Growth: "&TEXT(Inputs!C7,"0%")&" · Trading Period: May 2026 – Apr 2027") | J2: =TEXT(TODAY(),"DD MMM YYYY")
A3: ⭐ TOP 3 INVESTMENT HIGHLIGHTS
A4: =" 1. £"&TEXT('Dividend & Distribution Model'!B41,"#,##0")&" Year 1 investor return · "&TEXT('Dividend & Distribution Model'!B41/79000,"0.0%")&" cash-on-cash on £79,000 invested — pure pro-rata distribution" | E4: =" "&TEXT('Dividend & Distribution Model'!B41/79000,"0.0%")&" cash-on-cash on £79,000 invested — pure pro-rata, all shareholders paid by equity %"
A5: 2. Proven Borough Market venue | E5: £741,644 verified 2025 revenue · 90,475 venue page views · 58% organic search share — proven trading history
A6: 3. Founder-controlled growth plan | E6: DJ nights, corporate bookings & SEO programme — upside drivers not in the base case (£124k operating profit)
B9: 🏢 INVESTMENT SNAPSHOT | E9: 📊 FINANCIAL PERFORMANCE | H9: 💰 INVESTOR RETURNS | K9: 🏦 CASH & LIQUIDITY
B10: Investment Required | C10: ='Investment Valuation 1'!C13 | E10: 2025 Actual Revenue | F10: ='Monthly Summary'!C15 | H10: Year 1 Total Return | I10: ='Dividend & Distribution Model'!B41 | K10: Peak Cash Balance | L10: =MAX('Cash Flow Forecast'!B30:M30)
B11: Investor Equity | C11: ='Investment Valuation 1'!C19 | E11: Forecast Revenue | F11: ='Base Case Forecast'!N6 | H11: Preferred Return | I11: ='Dividend & Distribution Model'!B28 | K11: Minimum Cash Balance | L11: =MIN('Cash Flow Forecast'!B30:M30)
B12: Founder Equity | C12: ='Investment Valuation 1'!C18 | E12: Revenue Growth vs 25 | F12: =Inputs!C7 | H12: Pro-Rata Dividend | I12: ='Dividend & Distribution Model'!B30 | K12: Month of Lowest Cash | L12: ='Cash Flow Forecast'!G41
B13: Pre-Money Valuation | H13: Cash-on-Cash (Yr 1)
B14: Post-Money Valuation | E14: Forecast Profit | F14: ='Dividend & Distribution Model'!B14 | H14: Payback Period | K14: Cash Buffer vs Floor
B15: EBITDA (2025 actual) | E15: Op Costs (excl sal) | F15: ='Base Case Forecast'!N11 | H15: 5-Year IRR | K15: Cash-Positive Months
B16: Valuation Multiple | E16: Director Salary | F16: ='Base Case Forecast'!B54 | H16: Investor Equity % | K16: Day 1 Cash Position
B17: Share Class
B18: A/B Threshold | H18: 📣 MARKETING ENGINE (Google Ads — Base Case)
B19: Operating Profit | E19: ='Dividend & Distribution Model'!B26 | H19: Annual Ad Budget | K19: ='Google Budget'!F63
B20: − A-Share Priority Return | E20: =-'Dividend & Distribution Model'!B27 | H20: Weekly Budget | K20: ='Google Budget'!D62
B21: − Investor Preferred Ret. | E21: =-'Dividend & Distribution Model'!B28 | H21: Adjusted CPC (verified) | K21: ='Google Budget'!F65
B22: = Remaining Pool | E22: ='Dividend & Distribution Model'!B29 | H22: Annual Clicks | K22: ='Google Budget'!F75
B23: Investor Dividend | E23: ='Dividend & Distribution Model'!B30 | H23: Actual Paying Customers | K23: ='Google Budget'!F77
B24: Founder Dividend | E24: ='Dividend & Distribution Model'!B31 | H24: Incremental Revenue | K24: ='Google Budget'!F79
B25: ━ Total → Investor | E25: ='Dividend & Distribution Model'!B41 | H25: Net Profit from Ads | K25: ='Google Budget'!F81
B26: ━ Total → Founder | E26: ='Dividend & Distribution Model'!B40 | H26: Marketing ROAS | K26: ='Google Budget'!F87
B29: May | C29: Jun | D29: Jul | E29: Aug | F29: Sep | G29: Oct | H29: Nov | I29: Dec | J29: Jan | K29: Feb | L29: Mar | M29: Apr | N29: Founder Repayment | O29: ='Dividend & Distribution Model'!B27
B30: ='Base Case Forecast'!B6 | C30: ='Base Case Forecast'!C6 | D30: ='Base Case Forecast'!D6 | E30: ='Base Case Forecast'!E6 | F30: ='Base Case Forecast'!F6 | G30: ='Base Case Forecast'!G6 | H30: ='Base Case Forecast'!H6 | I30: ='Base Case Forecast'!I6 | ... M30: ='Base Case Forecast'!M6 | N30: Preferred Return | O30: ='Dividend & Distribution Model'!B28
B31: ='Base Case Forecast'!B16 | C31: ='Base Case Forecast'!C16 | D31: ='Base Case Forecast'!D16 | E31: ='Base Case Forecast'!E16 | F31: ='Base Case Forecast'!F16 | G31: ='Base Case Forecast'!G16 | H31: ='Base Case Forecast'!H16 | I31: ='Base Case Forecast'!I16 | ... M31: ='Base Case Forecast'!M16 | N31: Investor Dividend | O31: ='Dividend & Distribution Model'!B30
N32: Founder Dividend | O32: ='Dividend & Distribution Model'!B31
A33: Cumulative Cash Balance | B33: ='Cash Flow Forecast'!B30 | C33: ='Cash Flow Forecast'!C30 | D33: ='Cash Flow Forecast'!D30 | E33: ='Cash Flow Forecast'!E30 | F33: ='Cash Flow Forecast'!F30 | G33: ='Cash Flow Forecast'!G30 | H33: ='Cash Flow Forecast'!H30 | I33: ='Cash Flow Forecast'!I30 | ... M33: ='Cash Flow Forecast'!M30 | N33: 3-Month Reserve Target | O33: 142334
A34: ★ RESERVE NOTE: Red = below 2-month minimum. Amber = above 2-month, below 3-month target. Green = 3-month target met. The £11,022 working-capital residual + early-month trading cash flow fund the reserve. Year 1 distributions are payable from operating profit per the pure pro-rata waterfall above.
B54: 📈 KEY GROWTH DRIVERS | H54: ⚠ RISKS & MITIGATIONS
B55: ▶ Borough Market venue — 90,475 page views (2025) | H55: Marketing variability | J55: ✓ Conservative CPC/CVR; 3 verified scenarios modelled
B56: ▶ December peak month: £144k forecast revenue | H56: Seasonality (May–Jul) | J56: ✓ Cash buffer built in; deposit covers first 3 months
B57: ▶ DJ nights & live events (Fri/Sat) | H57: Cost overruns | J57: ✓ 30% hard cap on variable costs in all scenarios
B59: ▶ Corporate & private hire bookings | H59: Competitor risk | J59: ✓ Plonk IP and goodwill acquired; strong SEO moat
B60: ▶ Gaming repricing uplift (+£1 per game) | H60: Cash dip (Feb) | J60: ✓ Largest rent payment (Nov+Dec+Jan); modelled explicitly
B61: ▶ Organic search: 58% of all traffic — zero cost | H61: Profit concentration | J61: ✓ December = 28% of profit; mitigated by events programme
A63: ="No Dice Borough LTD · Investor Summary · All figures live-linked to financial model · Generated: "&TEXT(TODAY(),"DD MMM YYYY")&" · Confidential"
A66: 📋 INVESTMENT CASE & MARKET CONTEXT — Valuation rationale & investment thesis
A67: Market data: CLFI M&A Monitor H1 2025 · Houlihan Lokey Hospitality H1 2025 · UKHospitality · Moore Kingston Smith 2025 · UK Government Budget Factsheet
...

Sheet Investment Valuation 1
A1: ⚠ EDIT ONLY YELLOW CELLS — ALL OTHER CELLS ARE LOCKED AND PROTECTED
A2: NO DICE BOROUGH — INVESTMENT VALUATION | SHEET 1
A3: No Dice Borough LTD | Purchase from Liquidation | Prepared for Investor & Stakeholder Discussions | Confidential
A5: SECTION 1 — HEADLINE VALUATION SUMMARY
A6: Annual EBITDA | B6: EBITDA × 3.5 | C6: Pre-Money Value | D6: + Investment | E6: Post-Money Value | F6: Founder Retains | G6: Investor Receives
A7: ='Monthly Summary'!I15 | B7: ='Founder Tools'!C5 | C7: =A7*B7 | D7: 79000 | E7: =C7+D7 | F7: =C7/E7 | G7: =1-F7
A9: SECTION 2 — VALUATION BUILD
A10: Component | C10: £ Amount | E10: Cumulative | G10: Notes
A11: 2025 Annual Profit (EBITDA) | C11: ='Monthly Summary'!I15 | E11: ='Monthly Summary'!I15 | G11: Verified 52-week trading profit, exc. VAT
A12: × 0.86 EBITDA Multiple — Pre-Money (distressed entry) | C12: =C11*B7 | E12: =C11 | G12: 0.86× reflects distressed acquisition pricing. Sectoral comp is 4.1×.
A13: + £79,000 Investment | C13: 79000 | E13: =C11+C12 | G13: Investor capital injected into business on reopening Day 1 (May 2026). Inc VAT.
A14: POST-MONEY VALUATION | C14: =C13+C12 | E14: =C13+C12 | G14: Total company value at close — basis for shareholding
A16: SECTION 3 — SHAREHOLDING CALCULATION
A17: Party | C17: Shareholding % | E17: Basis | G17: Notes
A18: No Dice Borough LTD (Founder) | C18: =C12/C14 | E18: Pre-money ÷ Post-money (updates with multiple) | G18: Founder retains 50% controlling stake
A19: Investor | C19: =C13/C14 | E19: £70,000 ÷ Post-money valuation (updates with multiple) | G19: Investor — 50% equity. A Shares (≥5% threshold = £7,900). Below £7,900 = B Shares (economic only).
A20: TOTAL | C20: =C18+C19 | E20: Sum of both parties = 100%
A21: 📋 SHARE CLASS NOTE: At £79,000 investment (50% equity), the investor holds A Shares (full voting rights). A/B threshold is £7,900 (5% of post-money). Below £7,900 → B Shares (economic only).
A22: SECTION 4 — USE OF INVESTMENT FUNDS (£79,000 inc VAT)
A23: Item | B23: VAT | C23: Amount (inc VAT) | D23: % of Investment
A24: Hardware — Purchased from Liquidators | B24: inc VAT | C24: 24000 | D24: =C24/C13 | E24: Physical bar & kitchen equipment. Operational from Day 1.
A25: IP License Fee | B25: inc VAT | C25: 12000 | D25: =C25/C13 | E25: One-off licensing fee paid to No Dice Bars LTD — grants indefinite use of the Plonk name. No Dice Bars LTD also runs online sales campaigns and platform maintenance under an ongoing commission, replacing the old Design My Night bookings provider. See the Plonk tab for full IP & Licensing breakdown.
A26: Stock & Operational Setup | B26: inc VAT | C26: 4900 | D26: =C26/C13 | E26: Itemised £4,900 — opening alcohol stock, software subs, internet, cleaning restart, business rates (first month, VAT-exempt) + alcohol licence change (VAT-exempt). See breakdown rows 33-49.
A27: Landlord — 3 Months Rent in Advance | B27: inc VAT | C27: 27078 | D27: =C27/C13 | E27: 3 months rent paid up front — covers May, Jun, Jul 2026 at the contractual 15% of 2025 turnover rate. NO deposit required. From August 2026 rent reverts to 15% of actual quarterly turnover (variable, scales with trading).
A28: Working Capital Buffer | B28: — | C28: =C13-C24-C25-C26-C27 | D28: =C28/C13 | E28: Staged into business per cash flow model. Covers early trading before revenue covers costs.
A29: TOTAL INVESTMENT DEPLOYED | C29: =SUM(C24:C28) | D29: =C29/C13 | E29: All funds deployed on reopening day or staged per cash flow forecast.
A32: SECTION 4a — STOCK & OPERATIONAL SETUP DETAIL (£4,900 — inc VAT items + VAT-exempt regulatory costs)
A33: Item | B33: VAT basis | C33: Amount | D33: % of £4,900 | E33: Note
A34: Alcohol stock (opening fill) | B34: inc VAT | C34: 1500 | D34: =C34/4900 | E34: Wines, spirits, beer for Day 1 trading
A35: Soft drinks, mixers & non-alcohol stock | B35: inc VAT | C35: 300 | D35: =C35/4900 | E35: Mixers, juices, soft drinks opening fill
A36: Ice supplies (first delivery) | B36: inc VAT | C36: 30 | D36: =C36/4900 | E36: Daily delivery — first delivery only
A37: Cleaning contracts restart | B37: inc VAT | C37: 250 | D37: =C37/4900 | E37: Deep clean + first month commercial cleaning
A38: Internet — Starlink / BT Business (setup + 1 mo) | B38: inc VAT | C38: 300 | D38: =C38/4900 | E38: Hardware setup + first month connectivity
A39: App & booking platform setup | B39: inc VAT | C39: 200 | D39: =C39/4900 | E39: Plonk Golf booking + delivery app integrations
A40: Xero accounting (3 months) | B40: inc VAT | C40: 75 | D40: =C40/4900 | E40: £25/mth × 3 — cloud accounting
A41: Rota Cloud — staff scheduling (3 months) | B41: inc VAT | C41: 75 | D41: =C41/4900 | E41: £25/mth × 3 — rota & timesheet system
A42: Google Workspace (3 months) | B42: inc VAT | C42: 75 | D42: =C42/4900 | E42: Email + Drive + collab tools, 2 users
A43: Spotify Business (3 months) | B43: inc VAT | C43: 60 | D43: =C43/4900 | E43: £20/mth × 3 — bar music licensing
A44: Supplier contract deposits | B44: inc VAT | C44: 135 | D44: =C44/4900 | E44: Water, refuse, gas/electricity meter deposits
A45: Business rates (first month) | B45: VAT-exempt | C45: 1800 | D45: =C45/4900 | E45: First month UK business rates — Southwark Council, post-relief
...

Sheet Investment Rounds Model
A1: NO DICE BOROUGH LTD — INVESTMENT STRUCTURE MODEL | Share Classes · Dilution · Buyback · Returns
A2: ⚠ Yellow cells are editable inputs. All other cells are formula-driven. Live-linked to Investment Valuation 1 and Base Case Forecast.
A4: SECTION 1 — SHARE CLASS STRUCTURE
A5: Share Class | B5: Holder | C5: Voting Rights | D5: Economic Rights | E5: Transferability | F5: Drag-Along | G5: Tag-Along | H5: Anti-Dilution | I5: Notes
A6: A Shares | B6: No Dice Borough LTD (Founder / Elliot Scott) | C6: ✓ Full voting | D6: ✓ Full economic | E6: Restricted — founder consent required | F6: ✓ Can drag investors | G6: ✗ No tag-along | H6: N/A — protected class | I6: Ordinary shares with full control rights. Founder holds all A shares.
A7: B Shares | B7: Investor(s) | C7: ✗ No voting rights | D7: ✓ Full economic | E7: Restricted — board approval | F7: ✓ Subject to drag | G7: ✓ Tag-along on exit | H7: ✓ Broad-based weighted avg | I7: Preference shares, economic rights only. Issued exclusively to investors.
A8: ⚡ A/B SHARE THRESHOLD: Investors holding ≥5% of post-money (£7,900+) hold A Shares (voting rights). Below 5% → B Shares (economic rights only).
A9: Investment Amount | B9: Equity % | C9: Share Class | D9: Voting Rights | E9: Economic Rights
A10: ✓ Full economic
A11: £7,900 | B11: 5.00% | C11: ← A/B THRESHOLD | H11: Gain / (Loss) | I11: Status
A12: £10,000 | B12: 6.33% | C12: A Shares | D12: ✓ Full voting | E12: ✓ Full economic | H12: =ROUND('Investment Valuation 1'!C12*'Investment Valuation 1'!C18,2) | I12: Founder — controlling shareholder
A13: £25,000 | B13: 15.82% | C13: A Shares | D13: ✓ Full voting | E13: ✓ Full economic | H13: =ROUND('Investment Valuation 1'!C12*'Investment Valuation 1'!C19-'Investment Valuation 1'!C13,2) | I13: Seed investor — B shares, economic rights only
A14: £50,000 | B14: 31.65% | C14: A Shares | D14: ✓ Full voting | E14: ✓ Full economic | H14: =H12+H13 | I14: ✓ OK
A15: £79,000 | B15: 50.00% | C15: A Shares | D15: ✓ Full voting | E15: ✓ Full economic
A18: Founder Ownership % | B18: ='Investment Valuation 1'!C18
A19: Investor Ownership % | B19: ='Investment Valuation 1'!C19
A20: Voting Control | B20: 50/50 split — Founder and Investor both hold A Shares (≥5% threshold each)
A21: Total Shares in Issue | B21: =C14
A22: Founder Shares (A) | B22: =C12
A23: Investor Shares (B) | B23: =C13
A24: Pre-Money Valuation | B24: ='Investment Valuation 1'!C12
A25: Post-Money Valuation | B25: ='Investment Valuation 1'!C14
A26: Ownership Validation | B26: ✓ OK
A29: SECTION 4 — DILUTION MODEL | New rounds are B shares only | Toggle founder participation below
A30: INPUTS — Round 2 parameters
A31: Founder Participates in Round 2? | B31: No | C31: If Yes → Founder invests pro-rata to maintain %. If No → Founder dilutes.
A32: New Investment (Round 2) — £ | B32: 1000000 | C32: New cash injected. Issued as B shares only.
A33: Pre-Money Valuation — Round 2 | B33: 2000000 | C33: Agreed pre-money valuation at Round 2. Edit this cell.
A34: Founder Top-Up (if participates) | B34: 0 | C34: Amount founder invests if toggle = Yes. Set to 0 if No.
A36: DILUTION CALCULATIONS
A37: Metric | B37: Round 1 (Seed) | C37: Round 2 (New) | D37: Change | E37: Notes
A38: Pre-Money Valuation | B38: ='Investment Valuation 1'!C12 | C38: =B33 | D38: =C38-B38 | E38: Agreed company value before new money enters
A39: New Investment | B39: ='Investment Valuation 1'!C13 | C39: =B32 | D39: =C38-B38 | E39: Cash injected in this round (B shares)
A40: Post-Money Valuation | B40: ='Investment Valuation 1'!C14 | C40: =B33+B32+IF(B31="Yes",B34,0) | D40: =C38-B38 | E40: Pre-money + total investment including founder top-up
A41: Founder Ownership % | B41: ='Investment Valuation 1'!C18 | C41: =IF(B31="Yes",('Investment Valuation 1'!C18*B33+B34)/(B33+B32+B34),'Investment Valuation 1'!C18*B33/(B33+B32)) | D41: =C38-B38 | E41: Dilutes if no participation; maintained if founder tops up pro-rata
A42: Investor (R1) Ownership % | B42: ='Investment Valuation 1'!C19 | C42: ='Investment Valuation 1'!C19*B33/(B33+B32+IF(B31="Yes",B34,0)) | D42: =C38-B38 | E42: R1 investor always dilutes proportionally by new money
A43: New Investor (R2) Ownership % | B43: 0% | C43: =B32/(B33+B32+IF(B31="Yes",B34,0)) | D43: =C38-B38 | E43: New B shares issued to Round 2 investor
A44: OWNERSHIP TOTAL (must = 100%) | B44: =B41+B42 | C44: =C41+C42+C43 | E44: =IF(ABS(C44-1)<0.001,"✓ Valid — sums to 100%","✗ ERROR — check inputs")
A47: SECTION 5 — PRE-EMPTION RIGHTS MODEL
A48: The Founder holds statutory pre-emption rights on all future share issuances. If the Founder exercises these rights in a new round, they invest pro-rata to maintain their ownership percentage. If waived, the Founder dilutes proportionally with all other existing shareholders. B shares issued in future rounds carry no voting rights regardless of holder.
...

Sheet Investor Returns
A1: ⚠ EDIT ONLY YELLOW CELLS — ALL OTHER CELLS ARE LOCKED AND PROTECTED
A2: NO DICE BOROUGH LTD — INVESTOR RETURNS ANALYSIS | Base Case (+15%) with Marketing
A3: Investment: £79,000 | Equity: 50% | Distribution: pure pro-rata (no preferred, no priority tiers)
A5: SECTION A — YEAR 1 INVESTOR RETURNS (Base Case, May 2026 – Apr 2027)
A6: Base Case Forecast profit after director salary = 'Base Case Forecast'!N15. Investor equity = 'Investment Valuation 1'!C18. All calculations are formula-driven.
A7: Metric | D7: Value | F7: Notes
A8: Forecast Revenue (Year 1, Base +15%) | D8: ='Base Case Forecast'!N6 | F8: Total revenue forecast May 2026–Apr 2027 from Base Case Forecast
A9: Forecast Profit after Director Salary | D9: ='Dividend & Distribution Model'!B14 | F9: Operating profit after £30,000 director salary
A10: Investor Equity % | D10: ='Investment Valuation 1'!C19 | F10: £79,000 ÷ £158,000 post-money valuation = 50.00%
A11: Investor Share of Year 1 Profit | D11: =ROUND('Dividend & Distribution Model'!B14*'Investment Valuation 1'!C19,2) | F11: Profit × equity %. Assumes profit distributed in full
A12: Investment Amount | D12: ='Investment Valuation 1'!C12 | F12: Total investment received May 2026
A13: Year 1 Cash-on-Cash Return | D13: =ROUND('Dividend & Distribution Model'!B14*'Investment Valuation 1'!C19/'Investment Valuation 1'!C12,4) | F13: Investor Year 1 profit share ÷ investment. Simple cash return.
A14: Simple Payback Period (years) | D14: =ROUND('Investment Valuation 1'!C12/('Dividend & Distribution Model'!B14*'Investment Valuation 1'!C19),2) | F14: Investment ÷ annual investor share. Assumes consistent profit.
A16: SECTION B — 5-YEAR INVESTOR PROJECTION (Revenue growth 7.5% pa, stable margins)
A17: Growth assumption: 7.5% revenue growth per year (conservative — between DJ nights scaling and corporate season maturing). Margin held at Year 1 Base Case level. Exit at Year 5 on 4× EBITDA multiple. Edit growth rate in the Assumptions block below.
A18: Metric | B18: Year 1 2026/27 | C18: Year 2 2027/28 | D18: Year 3 2028/29 | E18: Year 4 2029/30 | F18: Year 5 2030/31 | G18: 5-Year Total | H18: Notes
A19: Revenue | B19: ='Base Case Forecast'!N6 | C19: =ROUND(B19*(1+$B$47),2) | D19: =ROUND(C19*(1+$B$47),2) | E19: =ROUND(D19*(1+$B$47),2) | F19: =ROUND(E19*(1+$B$47),2) | G19: =SUM(B19:F19) | H19: Annual trading revenue
A20: Profit (after dir. salary) | B20: ='Dividend & Distribution Model'!B14 | C20: =ROUND(C19*(B20/B19),2) | D20: =ROUND(D19*(C20/C19),2) | E20: =ROUND(E19*(D20/D19),2) | F20: =ROUND(F19*(E20/E19),2) | G20: =SUM(B20:F20) | H20: Operating profit at Year 1 margin %
A21: Profit Margin % | B21: =IF(B19<>0,B20/B19,0) | C21: =IF(C19<>0,C20/C19,0) | D21: =IF(D19<>0,D20/D19,0) | E21: =IF(E19<>0,E20/E19,0) | F21: =IF(F19<>0,F20/F19,0) | G21: =IF(G19<>0,G20/G19,0) | H21: Held at Year 1 Base Case margin
A22: Investor Share of Profit | B22: =ROUND(B20*'Investment Valuation 1'!C19,2) | C22: =ROUND(C20*'Investment Valuation 1'!C19,2) | D22: =ROUND(D20*'Investment Valuation 1'!C19,2) | E22: =ROUND(E20*'Investment Valuation 1'!C19,2) | F22: =ROUND(F20*'Investment Valuation 1'!C19,2) | G22: =SUM(B22:F22) | H22: Profit × 'Investment Valuation 1'!C18 investor equity
A23: Cumulative Cash Received | B23: =B22 | C23: =B23+C22 | D23: =C23+D22 | E23: =D23+E22 | F23: =E23+F22 | H23: Running total of investor profit shares
A25: SECTION C — YEAR 5 EXIT ANALYSIS (4× EBITDA Exit (entry at 3.5×))
A26: Year 5 EBITDA (Profit) | D26: =F20 | F26: Year 5 operating profit used as EBITDA proxy
A27: Exit Valuation Multiple | D27: =$B$48 | F27: 4× EBITDA for Year 5 exit — normalised going concern multiple. Entry multiple 3.5× (distressed). Exit at 4× reflects stabilised trading.
A28: Year 5 Business Valuation | D28: =ROUND(F20*$B$48,2) | F28: EBITDA × multiple = total business sale value
A29: Investor Exit Proceeds (equity share) | D29: =ROUND(F20*$B$48*'Investment Valuation 1'!C19,2) | F29: Business value × investor equity %
A30: Total Cash Returned (dividends + exit) | D30: =F22+ROUND(F20*$B$48*'Investment Valuation 1'!C19,2) | F30: 5 years of profit shares + exit proceeds
A31: Multiple of Money (MoM) | D31: =ROUND((F22+ROUND(F20*$B$48*'Investment Valuation 1'!C19,2))/'Investment Valuation 1'!C12,2) | F31: Total returned ÷ £79,000 invested. Target: positive cash-on-cash from Year 1.
A33: IRR CALCULATION — Internal Rate of Return
A34: Cash flows: Year 0 = -£79,000 (investment). Years 1-4 = investor profit share (50% pro-rata). Year 5 = profit share + exit proceeds at exit multiple. | B34: =-'Investment Valuation 1'!C12 | C34: =B22 | D34: =C22 | E34: =D22 | F34: =E22+ROUND(F20*$B$48*'Investment Valuation 1'!C19,2)
A35: Cash Flows for IRR | D35: =D21 | F35: =F21+ROUND(F19*$B$47*'Investment Valuation 1'!C19,2)
A36: INTERNAL RATE OF RETURN (IRR) | D36: =IRR(B34:F34) | F36: IRR of ~49% reflects high Year 1 returns and strong exit value. Hospitality sector IRR benchmark: 25-40%. This model comfortably exceeds it.
A46: SECTION D — PROJECTION ASSUMPTIONS (Edit these cells to update the model)
A47: Annual Revenue Growth Rate (Years 2-5) | B47: 0.075 | C47: Conservative: 7.5% pa. Edit to test different scenarios.
A48: Exit EBITDA Multiple (Year 5) | B48: 4 | C48: 4× EBITDA — Year 5 exit assumption (normalised). Entry: 3.5× (distressed). Range: 3× distressed to 5–6× premium.
A49: Year 1 Base Profit (from BCF) | B49: ='Base Case Forecast'!N15 | C49: Links live to Base Case Forecast — do not edit.
A50: Investor Equity (from valuation) | B50: ='Investment Valuation 1'!C19 | C50: Links live to Investment Valuation — do not edit.
A51: Investment Amount | B51: ='Investment Valuation 1'!C12 | C51: Links live to Investment Valuation — do not edit.
A53: 📋 SHARE CLASS NOTE: At £79,000 investment (50% equity), the investor holds A Shares (full voting). A/B threshold is £7,900 (5% of post-money). Below £7,900 → B Shares (economic only).

Sheet Dividend & Distribution Model
A1: NO DICE BOROUGH LTD · PROFIT DISTRIBUTION & INVESTOR RETURNS
A3: 📋 WHAT DOES THE INVESTOR RECEIVE? (Base Case)
A4: Investment Amount
A5: Total Year 1 Return | E5: =B40
A6: Cash-on-Cash Yr 1 | E6: ='Investor Returns'!D13
A7: Payback Period | E7: =ROUND('Investor Returns'!D14,1)
A9: NO DICE BOROUGH LTD — DIVIDEND & DISTRIBUTION MODEL | Founder Repayment · Investor Returns · Profit Waterfall
A10: ⚠ Yellow cells are editable inputs. All other cells are formula-driven and live-linked to the model.
A12: ⚙ MODEL INPUTS — Edit yellow cells to change assumptions
A13: ANNUAL PROFIT | B13: Value | C13: Source / Formula
A14: Annual Profit (Base Case — live) | B14: 124000 | C14: 124000 | E14: Hardcoded to £124,000 — presentation's 2026 base case under new cost model (wages +10%, fixed +10%, drinks = 30% of bar, hosting £3,492 fixed, everything else scales).
A15: Annual Revenue (Base Case — live) | B15: ='Base Case Forecast'!N6 | C15: ='Base Case Forecast'!N6 | E15: Live-linked to Base Case Forecast N6. Total forecast revenue.
A16: FOUNDER REPAYMENT
A17: Quarterly Founder Repayment | B17: 0 | E17: Removed — pure pro-rata distribution. All shareholders paid by equity % at the same time.
A18: Annual Founder Repayment (derived) | B18: =B17*4 | C18: B9 × 4 | E18: Quarterly repayment × 4. Auto-calculated. Edit quarterly figure above.
A19: OWNERSHIP & RETURNS
A20: Founder Ownership % | B20: ='Investment Valuation 1'!C18 | C20: ='Investment Valuation 1'!C18 | E20: Live-linked to Investment Valuation 1. Updates automatically if shareholding changes.
A21: Investor Ownership % | B21: ='Investment Valuation 1'!C19 | C21: ='Investment Valuation 1'!C19 | E21: Investor B-share equity %. Note: at 31.79% the investor holds A Shares (voting). The A/B threshold is 10% of post-money (£47,182). Economic returns are identical for A and B shares — only voting rights differ.
A22: Total Investment Raised | B22: ='Investment Valuation 1'!C13 | C22: ='Investment Valuation 1'!C13 | E22: Live-linked to Investment Valuation 1. £70,000 seed investment.
A23: Investor Preferred Return % (optional) | B23: 0 | C23: Editable input | E23: Removed — pure pro-rata. No preferred floor; investor return = profit × equity %.
A25: 💸 PROFIT DISTRIBUTION WATERFALL (in priority order)
A26: STEP 1 ↓ TOTAL PROFIT | B26: =B14 | C26: =B26 | D26: =IF(B26<>0,B26/B26,0) | E26: Full year operating profit — after all costs, VAT and director salary
A27: STEP 2 ↓ FOUNDER REPAYMENT (first, capped at profit) | B27: =MIN(ROUND(B22*B23,2),MAX(B26,0)) | C27: =B26-B27 | D27: =IF(B26<>0,B27/B26,0) | E27: Removed under pure pro-rata model. Set to 0.
A28: STEP 3 ↓ INVESTOR PREFERRED RETURN (guaranteed floor) | B28: =MIN(B18,MAX(B26-B27,0)) | C28: =C27-B28 | D28: =IF(B26<>0,B28/B26,0) | E28: Removed under pure pro-rata model. No preferred floor.
A29: STEP 4 ↓ REMAINING PROFIT AVAILABLE FOR DISTRIBUTION | B29: =MAX(B26-B27-B28,0) | C29: =B29 | D29: =IF(B26<>0,B29/B26,0) | E29: Profit − founder repayment − preferred return. This pool is split by share %
A30: STEP 5a → INVESTOR DIVIDEND (50% of profit) | B30: =ROUND(B29*B21,2) | C30: =B29-B30 | D30: =IF(B26<>0,B30/B26,0) | E30: Investor 50% equity stake applied to operating profit (pure pro-rata, no tiers).
A31: STEP 5b → FOUNDER DIVIDEND (50% of profit) | B31: =ROUND(B29*B20,2) | C31: — | D31: =IF(B26<>0,B31/B26,0) | E31: Founder 50% equity stake applied to operating profit (pure pro-rata, no tiers).
A33: 📊 DISTRIBUTION SUMMARY — Where every £ of profit goes
A34: Total Operating Profit | B34: =B26 | C34: =IF(B26<>0,B34/B26,0) | D34: — | E34: Starting profit pool. All distributions drawn from here.
A35: Investor Preferred Return (Step 2) | B35: =B27 | C35: =IF(B26<>0,B35/B26,0) | D35: Investor(s)
A36: Founder Repayment (Step 3) | B36: =B28 | C36: =IF(B26<>0,B36/B26,0) | D36: Founder (Elliot Scott)
A37: Investor Pro-Rata Dividend (Step 5a) | B37: =B30 | C37: =IF(B26<>0,B37/B26,0) | D37: Investor(s)
A38: Founder Pro-Rata Dividend (Step 5b) | B38: =B31 | C38: =IF(B26<>0,B38/B26,0) | D38: Founder (Elliot Scott)
A39: TOTAL DISTRIBUTED | B39: =B35+B36+B37+B38 | C39: =IF(B26<>0,B39/B26,0) | D39: All parties
A40: Total to Founder (Steps 2 + 5b) | B40: =B35+B37 | C40: =IF(B26<>0,B40/B26,0) | D40: Founder (Elliot Scott)
A41: Total to Investor (Steps 3 + 5a) | B41: =B36+B38 | C41: =IF(B26<>0,B41/B26,0) | D41: Investor(s) | E41: Preferred return + pro-rata dividend combined.
A42: Retained in Business (Profit − Distributed)
A43: ✅ CASH FLOW SAFETY CHECKS — Model validation
A44: Profit covers full founder repayment? | B44: =IF(B26>=B18,"✓ YES — full £"&TEXT(B18,"#,##0")&" payable","⚠ PARTIAL — only £"&TEXT(B27,"#,##0")&" of £"&TEXT(B18,"#,##0")&" payable") | C44: =B27 | D44: Founder repayment capped at available profit. No negative cash possible.
A45: Profit remaining after founder repayment | B45: =IF(MAX(B26-B27,0)>0,"✓ £"&TEXT(MAX(B26-B27,0),"#,##0")&" available for distributions","⚠ No profit remaining after repayment") | C45: =MAX(B26-B27,0) | D45: Profit left to fund preferred return and pro-rata dividends.
...

Sheet Cash Flow Forecast
A1: ⚠ EDIT ONLY YELLOW CELLS — ALL OTHER CELLS ARE LOCKED AND PROTECTED
A2: NO DICE BOROUGH — CASH FLOW FORECAST | May 2026 – April 2027 (Base Case +15%)
A3: Investment: £79,000 inc VAT | Startup: £67,978 inc VAT | Rent in Advance: £27,078 (3 months — May, Jun, Jul 2026) | Working Capital residual: £11,022
A4: ITEM | O4: Balance Check | P4: Status
A5: CASH IN | B5: May | C5: Jun | D5: Jul | E5: Aug | F5: Sep | G5: Oct | H5: Nov | I5: Dec | J5: Jan | K5: Feb | L5: Mar | M5: Apr | N5: TOTAL
A6: Investment Received (day 1 — May 2026) | B6: ='Investment Valuation 1'!C13 | N6: ='Investment Valuation 1'!C13
A7: Trading Income (inc VAT, +15% on 2025 equiv month) | B7: ='Base Case Forecast'!B6 | C7: ='Base Case Forecast'!C6 | D7: ='Base Case Forecast'!D6 | E7: ='Base Case Forecast'!E6 | F7: ='Base Case Forecast'!F6 | G7: ='Base Case Forecast'!G6 | H7: ='Base Case Forecast'!H6 | I7: ='Base Case Forecast'!I6 | ... N7: ='Base Case Forecast'!N6
A8: VAT Reclaim — Startup Costs (credited against Q1 return, Aug 2026) | B8: =ROUND(('Investment Valuation 1'!C24+'Investment Valuation 1'!C25+'Investment Valuation 1'!C26)/6,2) | N8: =ROUND(('Investment Valuation 1'!C24+'Investment Valuation 1'!C25+'Investment Valuation 1'!C26)/6,2)
A9: TOTAL CASH IN | B9: =B6+B7+B8 | C9: =C6+C7+C8 | D9: =D6+D7+D8 | E9: =E6+E7+E8 | F9: =F6+F7+F8 | G9: =G6+G7+G8 | H9: =H6+H7+H8 | I9: =I6+I7+I8 | ... M9: =M6+M7+M8 | N9: =SUM(B9:M9)
A11: ONE-OFF STARTUP COSTS (paid from investment — May 2026) | B11: May | C11: Jun | D11: Jul | E11: Aug | F11: Sep | G11: Oct | H11: Nov | I11: Dec | J11: Jan | K11: Feb | L11: Mar | M11: Apr | N11: TOTAL
A12: Hardware from Liquidators (£20k + VAT) | B12: ='Investment Valuation 1'!C24 | N12: ='Investment Valuation 1'!C24
A13: IP License Fee (paid to No Dice Bars LTD — £10k + VAT) | B13: ='Investment Valuation 1'!C25 | N13: ='Investment Valuation 1'!C25
A14: Stock & Operational Setup (£4,900 — alcohol, software subs, internet, cleaning, rates first month, alcohol licence) | B14: ='Investment Valuation 1'!C26 | N14: ='Investment Valuation 1'!C26
A15: Landlord — 3-Month Rent in Advance (covers May, Jun, Jul 2026 at 15% of 2025 turnover; reverts to 15% of actual turnover from August) | B15: ='Investment Valuation 1'!C27 | N15: ='Investment Valuation 1'!C27
A16: TOTAL ONE-OFF COSTS | B16: =B12+B13+B14+B15 | N16: =N12+N13+N14+N15
A18: MONTHLY OPERATING COSTS (wages + overheads at 2025 base + 10% fixed | rent quarterly in arrears at 15% of prev quarter revenue from August 2026) | B18: May | C18: Jun | D18: Jul | E18: Aug | F18: Sep | G18: Oct | H18: Nov | I18: Dec | J18: Jan | K18: Feb | L18: Mar | M18: Apr | N18: TOTAL
A19: Wages (held at 2025 actuals) | B19: ='Base Case Forecast'!B8 | C19: ='Base Case Forecast'!C8 | D19: ='Base Case Forecast'!D8 | E19: ='Base Case Forecast'!E8 | F19: ='Base Case Forecast'!F8 | G19: ='Base Case Forecast'!G8 | H19: ='Base Case Forecast'!H8 | I19: ='Base Case Forecast'!I8 | ... N19: ='Base Case Forecast'!N8
A20: Director Salary — Elliot Scott (£30,000 pa / £2,500/month) | B20: ='Base Case Forecast'!B12 | C20: ='Base Case Forecast'!C12 | D20: ='Base Case Forecast'!D12 | E20: ='Base Case Forecast'!E12 | F20: ='Base Case Forecast'!F12 | G20: ='Base Case Forecast'!G12 | H20: ='Base Case Forecast'!H12 | I20: ='Base Case Forecast'!I12 | ... N20: ='Base Case Forecast'!N12
A21: Fixed Overheads (2025 base + 10% — energy, insurance, subscriptions, business rates ~£1,800/mo from June) | B21: ='Base Case Forecast'!B9 | C21: ='Base Case Forecast'!C9 | D21: ='Base Case Forecast'!D9 | E21: ='Base Case Forecast'!E9 | F21: ='Base Case Forecast'!F9 | G21: ='Base Case Forecast'!G9 | H21: ='Base Case Forecast'!H9 | I21: ='Base Case Forecast'!I9 | ... N21: ='Base Case Forecast'!N9
A22: Variable Costs (2025 base, capped at 30% of revenue) | B22: ='Base Case Forecast'!B10 | C22: ='Base Case Forecast'!C10 | D22: ='Base Case Forecast'!D10 | E22: ='Base Case Forecast'!E10 | F22: ='Base Case Forecast'!F10 | G22: ='Base Case Forecast'!G10 | H22: ='Base Case Forecast'!H10 | I22: ='Base Case Forecast'!I10 | ... N22: ='Base Case Forecast'!N10
A23: Rent — From August 2026: 15% of prev quarter revenue, paid quarterly in arrears (May–Jul rent prepaid via the £27,078 advance, NOT a refundable deposit) | B23: ='Base Case Forecast'!B13 | C23: ='Base Case Forecast'!C13 | D23: ='Base Case Forecast'!D13 | E23: ='Base Case Forecast'!E13 | F23: ='Base Case Forecast'!F13 | G23: ='Base Case Forecast'!G13 | H23: ='Base Case Forecast'!H13 | I23: ='Base Case Forecast'!I13 | ... N23: ='Base Case Forecast'!N13
A24: VAT Output — Quarterly Payment to HMRC | B24: 0 | C24: 0 | D24: 0 | E24: =MAX(0,ROUND('Base Case Forecast'!B14+'Base Case Forecast'!C14+'Base Case Forecast'!D14,2)-'Cash Flow Forecast'!C8) | F24: 0 | G24: 0 | H24: =ROUND('Base Case Forecast'!E14+'Base Case Forecast'!F14+'Base Case Forecast'!G14,2) | I24: 0 | J24: 0 | K24: =ROUND('Base Case Forecast'!H14+'Base Case Forecast'!I14+'Base Case Forecast'!J14,2) | L24: 0 | M24: 0 | N24: ='Base Case Forecast'!N14
A25: TOTAL MONTHLY COSTS | B25: =B19+B20+B21+B22+B23+B24 | C25: =C19+C20+C21+C22+C23+C24 | D25: =D19+D20+D21+D22+D23+D24 | E25: =E19+E20+E21+E22+E23+E24 | F25: =F19+F20+F21+F22+F23+F24 | G25: =G19+G20+G21+G22+G23+G24 | H25: =H19+H20+H21+H22+H23+H24 | I25: =I19+I20+I21+I22+I23+I24 | ... M25: =M19+M20+M21+M22+M23+M24 | N25: =SUM(B25:M25)
A27: NET CASH FLOW SUMMARY | B27: May | C27: Jun | D27: Jul | E27: Aug | F27: Sep | G27: Oct | H27: Nov | I27: Dec | J27: Jan | K27: Feb | L27: Mar | M27: Apr | N27: TOTAL
A28: TOTAL CASH OUT | B28: =B16+B25 | C28: =C25 | D28: =D25 | E28: =E25 | F28: =F25 | G28: =G25 | H28: =H25 | I28: =I25 | J28: =J25 | ... M28: =M25 | N28: =N16+N25
A29: NET CASH FLOW (In minus Out) | B29: =B9-B28 | C29: =C9-C28 | D29: =D9-D28 | E29: =E9-E28 | F29: =F9-F28 | G29: =G9-G28 | H29: =H9-H28 | I29: =I9-I28 | ... M29: =M9-M28 | N29: =SUM(B29:M29)
A30: CUMULATIVE CASH BALANCE | B30: =B29 | C30: =B30+C29 | D30: =C30+D29 | E30: =D30+E29 | F30: =E30+F29 | G30: =F30+G29 | H30: =G30+H29 | I30: =H30+I29 | J30: =I30+J29 | ... M30: =L30+M29 | N30: =M30
A32: RENT STRUCTURE: £27,078 inc VAT paid in May 2026 covers 3 months of rent IN ADVANCE (May, Jun, Jul). NOT a refundable deposit. From August 2026 rent reverts to the contractual 15% of the prior quarters actual revenue, billed quarterly in arrears.
A33: COST NOTE: December 2026 rent = £0 (paid in November). January 2027 rent = £0 (paid in November). February 2027 rent = £41,968 — this is the largest quarterly payment as it covers Nov+Dec+Jan, which includes the high-revenue Christmas period (Dec 2026 forecast: £144,366). The cumulative balance dips in August, November and February on rent payment months but recovers strongly from trading.
A34: CASH FLOW BALANCE CHECK (Opening + Net = Closing each month)
A35: Monthly balance check (✓=balanced): | B35: =IF(ABS(B29-B30)<0.01,"✓","✗") | C35: =IF(ABS((B30+C29)-C30)<0.01,"✓","✗") | D35: =IF(ABS((C30+D29)-D30)<0.01,"✓","✗") | E35: =IF(ABS((D30+E29)-E30)<0.01,"✓","✗") | F35: =IF(ABS((E30+F29)-F30)<0.01,"✓","✗") | G35: =IF(ABS((F30+G29)-G30)<0.01,"✓","✗") | H35: =IF(ABS((G30+H29)-H30)<0.01,"✓","✗") | I35: =IF(ABS((H30+I29)-I30)<0.01,"✓","✗") | J35: =IF(ABS((I30+J29)-J30)<0.01,"✓","✗") | ... M35: =IF(ABS((L30+M29)-M30)<0.01,"✓","✗") | N35: =IF(COUNTIF(B35:M35,"✓")=12,"✓ ALL OK","✗ "&(12-COUNTIF(B35:M35,"✓"))&" FAIL")
A36: Period
A37: CASH BUFFER ANALYSIS — Liquidity Risk Monitor
A38: Minimum Monthly Cash Balance (worst month) | G38: =MIN(B30:M30) | L38: The lowest the cumulative balance falls across all 12 months. February 2027 (rent month) is typically the trough.
A39: Safety Threshold (recommended minimum) | G39: 30000 | L39: £30,000 = approx 5 weeks of fixed operating costs. Edit this cell to change the threshold.
A40: Cash Buffer Above Safety Threshold | G40: =MIN(B30:M30)-G39 | L40: If this turns negative → the business may need a cash facility or cost reduction.
A41: Month of Minimum Cash Position | G41: {=INDEX({"May","Jun","Jul","Aug","Sep","Oct","Nov","Dec","Jan","Feb","Mar","Apr"},MATCH(MIN(B29:M29),B29:M29,0))} | L41: The month when cash is at its lowest — useful for investor liquidity planning.
A42: Cash Safety Status | G42: =IF(MIN(B30:M30)>=G39,"✓ SAFE — cash stays above threshold","⚠ MONITOR — cash approaches minimum safe level") | L42: Green if always above threshold, amber if it drops below at any point.
A43: Wages | B43: 2025 actual staff wages retained as base. Shown separately from Director Salary below.
A44: Director Salary | B44: £30,000 per annum = £2,500.00 per month, fixed. Paid to Elliot Scott as Managing Director. Shown as a separate cost line for investor clarity. Profit figures above this line are before this salary.
...

Sheet Base Case Forecast
A1: ⚠ EDIT ONLY YELLOW CELLS — ALL OTHER CELLS ARE LOCKED AND PROTECTED
A2: NO DICE BOROUGH — BASE CASE FORECAST | May 2026 – April 2027 | +15% Revenue
A3: Equiv. period base (2025 actuals): £741,644 → Forecast: £852,891 | Costs: 2025 base + 10% fixed | Variable capped @30% | Rent quarterly at 15% of prev quarter
A4: Metric | B4: May 2026 | C4: Jun 2026 | D4: Jul 2026 | E4: Aug 2026 | F4: Sep 2026 | G4: Oct 2026 | H4: Nov 2026 | I4: Dec 2026 | J4: Jan 2027 | K4: Feb 2027 | L4: Mar 2027 | M4: Apr 2027 | N4: PERIOD TOTAL
A5: 2025 EQUIV-MONTH INCOME (base) | B5: ='Monthly Summary'!C7 | C5: ='Monthly Summary'!C8 | D5: ='Monthly Summary'!C9 | E5: ='Monthly Summary'!C10 | F5: ='Monthly Summary'!C11 | G5: ='Monthly Summary'!C12 | H5: ='Monthly Summary'!C13 | I5: ='Monthly Summary'!C14 | J5: ='Monthly Summary'!C3 | K5: ='Monthly Summary'!C4 | L5: ='Monthly Summary'!C5 | M5: ='Monthly Summary'!C6 | N5: =SUM(B5:M5)
A6: 2026/27 FORECAST INCOME (scenario-driven growth, see Inputs) | B6: =ROUND(B5*(1+$B$52)*B60/$B$61,2) | C6: =ROUND(C5*(1+$B$52)*C60/$B$61,2) | D6: =ROUND(D5*(1+$B$52)*D60/$B$61,2) | E6: =ROUND(E5*(1+$B$52)*E60/$B$61,2) | F6: =ROUND(F5*(1+$B$52)*F60/$B$61,2) | G6: =ROUND(G5*(1+$B$52)*G60/$B$61,2) | H6: =ROUND(H5*(1+$B$52)*H60/$B$61,2) | I6: =ROUND(I5*(1+$B$52)*I60/$B$61,2) | ... M6: =ROUND(M5*(1+$B$52)*M60/$B$61,2) | N6: =SUM(B6:M6)
A7: REVENUE UPLIFT | B7: =B6-B5 | C7: =C6-C5 | D7: =D6-D5 | E7: =E6-E5 | F7: =F6-F5 | G7: =G6-G5 | H7: =H6-H5 | I7: =I6-I5 | ... M7: =M6-M5 | N7: =SUM(B7:M7)
A8: WAGES (2025 actuals) | B8: ='Monthly Summary'!G7 | C8: ='Monthly Summary'!G8 | D8: ='Monthly Summary'!G9 | E8: ='Monthly Summary'!G10 | F8: ='Monthly Summary'!G11 | G8: ='Monthly Summary'!G12 | H8: ='Monthly Summary'!G13 | I8: ='Monthly Summary'!G14 | J8: ='Monthly Summary'!G3 | K8: ='Monthly Summary'!G4 | L8: ='Monthly Summary'!G5 | M8: ='Monthly Summary'!G6 | N8: =SUM(B8:M8)
A9: FIXED OVERHEADS (2025 base +10%) | B9: =ROUND('Monthly Summary'!E7*(1+$B$53),2) | C9: =ROUND('Monthly Summary'!E8*(1+$B$53),2) | D9: =ROUND('Monthly Summary'!E9*(1+$B$53),2) | E9: =ROUND('Monthly Summary'!E10*(1+$B$53),2) | F9: =ROUND('Monthly Summary'!E11*(1+$B$53),2) | G9: =ROUND('Monthly Summary'!E12*(1+$B$53),2) | H9: =ROUND('Monthly Summary'!E13*(1+$B$53),2) | I9: =ROUND('Monthly Summary'!E14*(1+$B$53),2) | J9: =ROUND('Monthly Summary'!E3*(1+$B$53),2) | K9: =ROUND('Monthly Summary'!E4*(1+$B$53),2) | L9: =ROUND('Monthly Summary'!E5*(1+$B$53),2) | M9: =ROUND('Monthly Summary'!E6*(1+$B$53),2) | N9: =SUM(B9:M9)
A10: VARIABLE COSTS (capped @30%) | B10: =ROUND(MIN('Monthly Summary'!F7*(B6/'Monthly Summary'!C7),$B$55*B6),2) | C10: =ROUND(MIN('Monthly Summary'!F8*(C6/'Monthly Summary'!C8),$B$55*C6),2) | D10: =ROUND(MIN('Monthly Summary'!F9*(D6/'Monthly Summary'!C9),$B$55*D6),2) | E10: =ROUND(MIN('Monthly Summary'!F10*(E6/'Monthly Summary'!C10),$B$55*E6),2) | F10: =ROUND(MIN('Monthly Summary'!F11*(F6/'Monthly Summary'!C11),$B$55*F6),2) | G10: =ROUND(MIN('Monthly Summary'!F12*(G6/'Monthly Summary'!C12),$B$55*G6),2) | H10: =ROUND(MIN('Monthly Summary'!F13*(H6/'Monthly Summary'!C13),$B$55*H6),2) | I10: =ROUND(MIN('Monthly Summary'!F14*(I6/'Monthly Summary'!C14),$B$55*I6),2) | J10: =ROUND(MIN('Monthly Summary'!F3*(J6/'Monthly Summary'!C3),$B$55*J6),2) | K10: =ROUND(MIN('Monthly Summary'!F4*(K6/'Monthly Summary'!C4),$B$55*K6),2) | L10: =ROUND(MIN('Monthly Summary'!F5*(L6/'Monthly Summary'!C5),$B$55*L6),2) | M10: =ROUND(MIN('Monthly Summary'!F6*(M6/'Monthly Summary'!C6),$B$55*M6),2) | N10: =SUM(B10:M10)
A11: ALL OPERATING COSTS | B11: =B8+B9+B10 | C11: =C8+C9+C10 | D11: =D8+D9+D10 | E11: =E8+E9+E10 | F11: =F8+F9+F10 | G11: =G8+G9+G10 | H11: =H8+H9+H10 | I11: =I8+I9+I10 | ... M11: =M8+M9+M10 | N11: =SUM(B11:M11)
A12: Director Salary — Elliot Scott (£30,000 pa / £2,500/month fixed) | B12: =$B$54/12 | C12: =$B$54/12 | D12: =$B$54/12 | E12: =$B$54/12 | F12: =$B$54/12 | G12: =$B$54/12 | H12: =$B$54/12 | I12: =$B$54/12 | ... M12: =$B$54/12 | N12: =$B$54
A13: RENT (quarterly — Aug, Nov, Feb) | E13: =ROUND($B$56*(B6+C6+D6),2) | H13: =ROUND($B$56*(E6+F6+G6),2) | K13: =ROUND($B$56*(H6+I6+J6),2) | N13: =E13+H13+K13
A14: VAT DIFFERENCE | B14: =ROUND('Monthly Summary'!H7*(B6/'Monthly Summary'!C7),2) | C14: =ROUND('Monthly Summary'!H8*(C6/'Monthly Summary'!C8),2) | D14: =ROUND('Monthly Summary'!H9*(D6/'Monthly Summary'!C9),2) | E14: =ROUND('Monthly Summary'!H10*(E6/'Monthly Summary'!C10),2) | F14: =ROUND('Monthly Summary'!H11*(F6/'Monthly Summary'!C11),2) | G14: =ROUND('Monthly Summary'!H12*(G6/'Monthly Summary'!C12),2) | H14: =ROUND('Monthly Summary'!H13*(H6/'Monthly Summary'!C13),2) | I14: =ROUND('Monthly Summary'!H14*(I6/'Monthly Summary'!C14),2) | J14: =ROUND('Monthly Summary'!H3*(J6/'Monthly Summary'!C3),2) | K14: =ROUND('Monthly Summary'!H4*(K6/'Monthly Summary'!C4),2) | L14: =ROUND('Monthly Summary'!H5*(L6/'Monthly Summary'!C5),2) | M14: =ROUND('Monthly Summary'!H6*(M6/'Monthly Summary'!C6),2) | N14: =SUM(B14:M14)
A15: PROFIT BEFORE DIRECTOR SALARY | B15: =B6-B11-B14 | C15: =C6-C11-C14 | D15: =D6-D11-D14 | E15: =E6-E11-E14 | F15: =F6-F11-F14 | G15: =G6-G11-G14 | H15: =H6-H11-H14 | I15: =I6-I11-I14 | ... M15: =M6-M11-M14 | N15: =SUM(B15:M15)
A16: FORECAST PROFIT (after director salary of £30,000 pa) | B16: =B15-B12 | C16: =C15-C12 | D16: =D15-D12 | E16: =E15-E12 | F16: =F15-F12 | G16: =G15-G12 | H16: =H15-H12 | I16: =I15-I12 | ... M16: =M15-M12 | N16: =SUM(B16:M16)
A17: PROFIT MARGIN % | B17: =IF(B6<>0,B16/B6,0) | C17: =IF(C6<>0,C16/C6,0) | D17: =IF(D6<>0,D16/D6,0) | E17: =IF(E6<>0,E16/E6,0) | F17: =IF(F6<>0,F16/F6,0) | G17: =IF(G6<>0,G16/G6,0) | H17: =IF(H6<>0,H16/H6,0) | I17: =IF(I6<>0,I16/I6,0) | ... N17: =IF(N6<>0,N16/N6,0)
A19: RENT NOTE: Deposit of £27,078 covers months 1–3 (May, Jun, Jul). Rent paid quarterly: Aug 2026 = £25,992 | Nov 2026 = £31,659 | Feb 2027 = £41,968 | Total paid in period: £99,618 | Q4 rent £28,315 due May 2027. Full-year rent obligation (15% of £852,891): £127,934.
A20: PERIOD SUMMARY
A21: Metric | B21: 2025 Equiv Base | F21: 2026/27 Forecast | J21: Change £
A22: Revenue | B22: ='Monthly Summary'!C15 | F22: =N6 | J22: =N6-B22
A23: Operating Costs | B23: ='Monthly Summary'!D15 | F23: =N11 | J23: =N11-B23
A24: Forecast Profit (after director salary) | B24: ='Monthly Summary'!I15 | F24: =N16 | J24: =N16-B24
A28: FORECAST VALIDATION CHECKS — Independent recalculation (Expected ≠ Actual link)
A29: Each Expected value is INDEPENDENTLY recalculated from raw 2025 data and parameter cells. Status flips to ERROR if the model diverges from the formula by more than £1. Assumptions: B51=Growth%, B52=Fixed uplift%, B53=Dir salary, B54=Var cap, B55=Rent%.
A30: Check | B30: Expected (independent recalc) | C30: Actual (model reports) | D30: Δ Diff | E30: Status | F30: Δ Diff | G30: Status
A31: Revenue total — 2025 base × (1+growth%) × SW ÷ WGT | B31: =ROUND(SUMPRODUCT(B5:M5*(1+$B$52)*B60:M60/$B$61),2) | C31: =N6 | D31: =ABS(B31-C31) | E31: =IF(ABS(B31-C31)<1,"✓ OK","✗ ERROR")
A32: Fixed Overheads — 2025 base × (1+fixed uplift%) | B32: =ROUND('Monthly Summary'!E15*(1+$B$53),2) | C32: =N9 | D32: =ABS(B32-C32) | E32: =IF(ABS(B32-C32)<1,"✓ OK","✗ ERROR")
A33: Wages total — must equal 2025 actual wages exactly | B33: ='Monthly Summary'!G15 | C33: =N8 | D33: =ABS(B33-C33) | E33: =IF(ABS(B33-C33)<1,"✓ OK","✗ ERROR")
A34: Variable Costs — 2025 base scaled with revenue, capped | B34: =SUM(ROUND(MIN('Monthly Summary'!F7*(B6/'Monthly Summary'!C7),$B$55*B6),2),ROUND(MIN('Monthly Summary'!F8*(C6/'Monthly Summary'!C8),$B$55*C6),2),ROUND(MIN('Monthly Summary'!F9*(D6/'Monthly Summary'!C9),$B$55*D6),2),ROUND(MIN('Monthly Summary'!F10*(E6/'Monthly Summary'!C10),$B$55*E6),2),ROUND(MIN('Monthly Summary'!F11*(F6/'Monthly Summary'!C11),$B$55*F6),2),ROUND(MIN('Monthly Summary'!F12*(G6/'Monthly Summary'!C12),$B$55*G6),2),ROUND(MIN('Monthly Summary'!F13*(H6/'Monthly Summary'!C13),$B$55*H6),2),ROUND(MIN('Monthly Summary'!F14*(I6/'Monthly Summary'!C14),$B$55*I6),2),ROUND(MIN('Monthly Summary'!F3*(J6/'Monthly Summary'!C3),$B$55*J6),2),ROUND(MIN('Monthly Summary'!F4*(K6/'Monthly Summary'!C4),$B$55*K6),2),ROUND(MIN('Monthly Summary'!F5*(L6/'Monthly Summary'!C5),$B$55*L6),2),ROUND(MIN('Monthly Summary'!F6*(M6/'Monthly Summary'!C6),$B$55*M6),2)) | C34: =N10 | D34: =ABS(B34-C34) | E34: =IF(ABS(B34-C34)<1,"✓ OK","✗ ERROR")
A35: All Operating Costs = Wages + Fixed + Variable | B35: =N8+N9+N10 | C35: =N11 | D35: =ABS(B35-C35) | E35: =IF(ABS(B35-C35)<1,"✓ OK","✗ ERROR")
A36: Director Salary total = annual param | B36: =$B$54 | C36: =N12 | D36: =ABS(B36-C36) | E36: =IF(ABS(B36-C36)<1,"✓ OK","✗ ERROR")
A37: Profit before dir. salary = Revenue − OpCosts − VAT | B37: =N6-N11-N14 | C37: =N15 | D37: =ABS(B37-C37) | E37: =IF(ABS(B37-C37)<1,"✓ OK","✗ ERROR")
A38: Profit after dir. salary = Profit before − Dir Salary | B38: =N15-N12 | C38: =N16 | D38: =ABS(B38-C38) | E38: =IF(ABS(B38-C38)<1,"✓ OK","✗ ERROR")
A39: Rent paid = 15% of Q1+Q2+Q3 revenues | B39: =ROUND($B$56*(B6+C6+D6),2)+ROUND($B$56*(E6+F6+G6),2)+ROUND($B$56*(H6+I6+J6),2) | C39: =N13 | D39: =ABS(B39-C39) | E39: =IF(ABS(B39-C39)<1,"✓ OK","✗ ERROR")
A40: VAT difference — proportional to revenue | B40: =ROUND('Monthly Summary'!H15*(N6/'Monthly Summary'!C15),2) | C40: =N14 | D40: =ABS(B40-C40) | E40: =IF(ABS(B40-C40)<1,"✓ OK","✗ ERROR")
A42: FORMULA CONSISTENCY CHECK — All months must use identical formula structure
A43: Forecast Rev (row 6) | B43: Fixed OH (row 9) | C43: Variable (row 10) | D43: Profit (row 16) | E43: VAT (row 14)
A44: ✓ Consistent | B44: ✓ Consistent | C44: ✓ Consistent | D44: ✓ Consistent | E44: ✓ Consistent
A51: FORECAST ASSUMPTION INPUTS — Edit these cells to update the entire model
...

Sheet Scenario Planning
A1: ⚠ EDIT ONLY YELLOW CELLS — ALL OTHER CELLS ARE LOCKED AND PROTECTED
A2: NO DICE BOROUGH — SCENARIO PLANNING | May 2026 – April 2027
A3: Three revenue scenarios vs 2025 equivalent-month base of £741,644 | Costs: 2025 base + 10% fixed | Variable capped @30% | Rent quarterly in arrears at 15% | Deposit covers May–Jul
A5: HOW PROFIT IS CALCULATED
A6: Component | B6: Equiv Period 2025 | D6: Notes
A7: Total Revenue (May–Apr equiv period 2025) | B7: ='Monthly Summary'!C15 | D7: 12-month equivalent period using 2025 actuals
A8: Less: All Operating Costs | B8: =-'Monthly Summary'!D15 | D8: Wages + fixed overheads + variable costs
A9: Less: VAT Difference (net paid to HMRC) | B9: =-'Monthly Summary'!H15 | D9: Output VAT minus input VAT reclaimed — paid quarterly
A10: PROFIT (equiv period 2025) | B10: =B7+B8+B9 | D10: Base profit before forecast uplift
A12: KEY SEASONAL DRIVERS | May 2026 – April 2027
A13: Month | B13: 2025 Equiv | D13: Season Driver & Key Dates
A14: May 2026 | B14: ='Monthly Summary'!C3 | D14: Grand reopening | Bank hols 4 & 26 May | DJ nights launch | Garden season opens
A15: June 2026 | B15: ='Monthly Summary'!C3 | D15: Corporate Q2 close events | University leavers | Wimbledon late Jun | DJ nights
A16: July 2026 | B16: ='Monthly Summary'!C3 | D16: Schools out ~22 Jul | Families + student events | Weekly DJ nights | World Cup if applicable
A17: August 2026 | B17: ='Monthly Summary'!C3 | D17: ★★★ Peak — school holidays all month | Garden bar | DJ nights | Bank hol 31 Aug
A18: September 2026 | B18: ='Monthly Summary'!C3 | D18: ★★★ University FRESHERS mid-Sep — biggest new-customer window | Leagues restart
A19: October 2026 | B19: ='Monthly Summary'!C3 | D19: ★★ School half term 26–30 Oct | Halloween ticketed events | Corporate Q3 close
A20: November 2026 | B20: ='Monthly Summary'!C3 | D20: ★★★ Christmas corporate season starts | Office parties | DJ nights | Private hires
A21: December 2026 | B21: ='Monthly Summary'!C3 | D21: ★★★ PEAK — Christmas corporate + NYE | Proven £121k base in 2025
A22: January 2027 | B22: ='Monthly Summary'!C15 | D22: ★ Students return ~12 Jan | Post-Xmas quiet | DJ nights | Community leagues
A23: February 2027 | B23: ='Monthly Summary'!C3 | D23: Half term 16–20 Feb | Valentine's events | Q4 rent payment month
A24: March 2027 | B24: ='Monthly Summary'!C3 | D24: Corporate Q1 close events | Spring build | University term
A25: April 2027 | B25: ='Monthly Summary'!C3 | D25: ★ Easter 2–6 Apr | School half term | Last month of trading period
A27: ⚠ CONSERVATIVE — +10% | Target: £815,809 | Profit: £196,417 | Margin: 24.1%
A28: Lower relaunch. DJ programme building. Corporate season partially secured.
A29: =" Revenue Target: "&TEXT(P32,"£#,##0") | D29: =IF(P32>0,"Conservative Revenue: £"&TEXT(P32,"#,##0")&" | Uplift vs 2025: £"&TEXT(P32-'Monthly Summary'!C15,"#,##0"),"") | G29: Operating Costs: £532,309 | J29: Profit after dir. salary: £166,417 | M29: Rent Paid in Period: £95,162
A31: Metric | B31: May 2026 | C31: Jun 2026 | D31: Jul 2026 | E31: Aug 2026 | F31: Sep 2026 | G31: Oct 2026 | H31: Nov 2026 | I31: Dec 2026 | J31: Jan 2027 | K31: Feb 2027 | L31: Mar 2027 | M31: Apr 2027 | P31: TOTAL
A32: 2025 Equiv Revenue | B32: ='Monthly Summary'!C7*(1+$B$93) | C32: ='Monthly Summary'!C8*(1+$B$93) | D32: ='Monthly Summary'!C9*(1+$B$93) | E32: ='Monthly Summary'!C10*(1+$B$93) | F32: ='Monthly Summary'!C11*(1+$B$93) | G32: ='Monthly Summary'!C12*(1+$B$93) | H32: ='Monthly Summary'!C13*(1+$B$93) | I32: ='Monthly Summary'!C14*(1+$B$93) | J32: ='Monthly Summary'!C3*(1+$B$93) | K32: ='Monthly Summary'!C4*(1+$B$93) | L32: ='Monthly Summary'!C5*(1+$B$93) | M32: ='Monthly Summary'!C6*(1+$B$93) | P32: ='Monthly Summary'!C15
A33: +10% Target | B33: =B32 | C33: =C32 | D33: =D32 | E33: =E32 | F33: =F32 | G33: =G32 | H33: =H32 | I33: =I32 | ... M33: =M32 | P33: =SUM(B32:M32)
A34: Revenue Uplift | B34: =B32-B31 | C34: =C32-C31 | D34: =D32-D31 | E34: =E32-E31 | F34: =F32-F31 | G34: =G32-G31 | H34: =H32-H31 | I34: =I32-I31 | ... M34: =M32-M31 | P34: =SUM(B33:M33)
